Workbook

Sheet Resumo
A1: Produtos, preços e custos — Jacartta e Espaço de Bicho
A3: Shopee: 14/08/2026, 12:39:15 • custos Olist: 14/08/2026, 14:11:14 (horário de Brasília)
A5: Anúncios ativos | C5: Produtos/variações | E5: Em promoção | G5: Sem promoção
A6: 388 | C6: 700 | E6: 500 | G6: 200
A9: Resumo por loja
A10: Loja | B10: Anúncios | C10: Produtos/variações | D10: Em promoção | E10: Sem promoção | F10: % em promoção
A11: Espaço De Bicho | B11: 189 | C11: 286 | D11: 202 | E11: 84 | F11: 0.70629371
A12: Jacartta | B12: 199 | C12: 414 | D12: 298 | E12: 116 | F12: 0.71980676
A13: Total | B13: =SUBTOTAL(109,ResumoLojas[Anúncios]) | C13: =SUBTOTAL(109,ResumoLojas[Produtos/variações]) | D13: =SUBTOTAL(109,ResumoLojas[Em promoção]) | E13: =SUBTOTAL(109,ResumoLojas[Sem promoção]) | F13: =D13/C13
A15: Como interpretar os preços
A16: Preço final = preço promocional quando houver promoção ativa; caso contrário, preço de venda atual retornado pela Shopee.
A18: Fontes: Shopee Open Platform — https://partner.shopeemobile.com • Olist ERP/API — https://olist.com
A20: Cobertura dos custos Olist
A21: Loja | B21: Linhas | C21: Localizadas | D21: Custo > R$ 0 | E21: Custo R$ 0 | F21: Sem correspondência
A22: Espaço De Bicho | B22: 286 | C22: =COUNTIFS(Produtos!$A$5:$A$695,A22,Produtos!$O$5:$O$695,"<>") | D22: =COUNTIFS(Produtos!$A$5:$A$695,A22,Produtos!$O$5:$O$695,">0") | E22: =COUNTIFS(Produtos!$A$5:$A$695,A22,Produtos!$O$5:$O$695,"=0") | F22: =COUNTIFS(Produtos!$A$5:$A$695,A22,Produtos!$O$5:$O$695,"")
A23: Jacartta | B23: 414 | C23: =COUNTIFS(Produtos!$A$5:$A$695,A23,Produtos!$O$5:$O$695,"<>") | D23: =COUNTIFS(Produtos!$A$5:$A$695,A23,Produtos!$O$5:$O$695,">0") | E23: =COUNTIFS(Produtos!$A$5:$A$695,A23,Produtos!$O$5:$O$695,"=0") | F23: =COUNTIFS(Produtos!$A$5:$A$695,A23,Produtos!$O$5:$O$695,"")
A24: Total | B24: 700 | C24: =SUM(C22:C23) | D24: =SUM(D22:D23) | E24: =SUM(E22:E23) | F24: =SUM(F22:F23)
A26: Leitura: custo positivo = valor cadastrado; R$ 0,00 = produto localizado com custo zerado na Olist; vazio = sem correspondência exata segura.

Sheet Produtos
A1: Catálogo ativo com preços finais, promoções e custos Olist
A2: Uma linha por produto/variação. Custo Olist: R$ 0,00 = custo zerado no ERP; vazio = sem correspondência segura. | V2: Custo = preco_custo do cadastro Olist consultado hoje via API. QTD = unidades Olist por unidade do anúncio, derivada dos pedidos casados. | W2: Custo: anúncio de KIT usa o valor da aba de kits da Olist (componente × quantidade); produto unitário usa o preço de custo do cadastro. Conferido ao vivo em 16/08. Preços (I,K) do sync Shopee 16/08 ~13h50.
M3: ANÁLISE JULIANO | V3: PREENCHIDO PELO ORÁCULO — 16/08/2026 (custos conferidos AO VIVO na API da Olist)
A4: Loja | B4: Produto | C4: Variação | D4: SKU vendedor | E4: Item ID | F4: Variação ID | G4: Status | H4: Preço cadastrado | I4: Preço venda atual | J4: Em promoção? | K4: Preço promocional | L4: Preço final | M4: QTD | N4: Custo Unitário | O4: Custo Olist | P4: Lucro / Prejuizo | Q4: Desconto % | R4: ID(s) promoção | S4: Início promoção | T4: Fim promoção | U4: Categoria ID | V4: SKU Olist | W4: Origem do custo | X4: Pedidos casados | Y4: Checagem de modelo
A5: Espaço De Bicho | B5: 3 Rolos Removedor De Pelos Pet de Gato e Cachorro Removedor de pelos | C5: 2 UNIDADES | D5: 2-ROLO-REMOVEDOR | E5: 54964685255 | F5: 262815678259 | G5: NORMAL | H5: 89.9 | I5: 37.9 | J5: SIM | K5: 37.9 | L5: =IF(K5<>"",K5,I5) | O5: 28.65 | P5: =IF($O5="","",L5-O5-(L5*IF(L5<=79.99,20%,14%)+IF(L5<=79.99,4,IF(L5<=99.99,16,IF(L5<=199.99,20,IF(L5<=499.99,26,28)))))-L5*1.3%-L5*6%-(L5-O5)*9.25%-L5*3%-L5*3%-1) | Q5: =IF(AND(K5<>"",H5>0),(H5-K5)/H5,"") | R5: 909477973245952 | S5: 46144.383 | T5: 46295.438 | U5: 100929 | W5: custo preexistente (busca por texto) mantido
A6: Espaço De Bicho | B6: Adubo Fertilizante Mineral Forth Rosa Do Deserto 3kg/400g | C6: 3KG | D6: ADUBO-FORTH-ROSA-3KG | E6: 22593696013 | F6: 169406379212 | G6: NORMAL | H6: 79.9 | I6: 59.6 | J6: SIM | K6: 59.6 | L6: =IF(K6<>"",K6,I6) | M6: 1 | N6: 39.25 | O6: =ROUND(M6*N6,2) | P6: =IF($O6="","",L6-O6-(L6*IF(L6<=79.99,20%,14%)+IF(L6<=79.99,4,IF(L6<=99.99,16,IF(L6<=199.99,20,IF(L6<=499.99,26,28)))))-L6*1.3%-L6*6%-(L6-O6)*9.25%-L6*3%-L6*3%-1) | Q6: =IF(AND(K6<>"",H6>0),(H6-K6)/H6,"") | R6: 909477973245952 | S6: 46144.383 | T6: 46295.438 | U6: 101179 | V6: 213560 | W6: venda casada (10 pedidos) | X6: 10 | Y6: ok
A7: Espaço De Bicho | B7: Anti-Inflamatório Alcort Para Cachorros Com 10 Comprimidos De 5mg | C7: 5mg | D7: ALCORT-5MG-10COMP | E7: 22799241855 | F7: 109871690918 | G7: NORMAL | H7: 99.9 | I7: 99.9 | J7: NÃO | L7: =IF(K7<>"",K7,I7) | P7: =IF($O7="","",L7-O7-(L7*IF(L7<=79.99,20%,14%)+IF(L7<=79.99,4,IF(L7<=99.99,16,IF(L7<=199.99,20,IF(L7<=499.99,26,28)))))-L7*1.3%-L7*6%-(L7-O7)*9.25%-L7*3%-L7*3%-1) | Q7: =IF(AND(K7<>"",H7>0),(H7-K7)/H7,"") | U7: 100942 | V7: ALCORT-5MG-10COMP | W7: SKU idêntico na Olist · CUSTO ZERADO na Olist (conferido hoje) | Y7: ok
A8: Espaço De Bicho | B8: Antipulgas E Carrapatos Frontline Top Spot Gato 1 A 10kg | C8: Sem variação | D8: 0667 | E8: 20959149444 | F8: 0 | G8: NORMAL | H8: 38.9 | I8: 38.9 | J8: NÃO | L8: =IF(K8<>"",K8,I8) | P8: =IF($O8="","",L8-O8-(L8*IF(L8<=79.99,20%,14%)+IF(L8<=79.99,4,IF(L8<=99.99,16,IF(L8<=199.99,20,IF(L8<=499.99,26,28)))))-L8*1.3%-L8*6%-(L8-O8)*9.25%-L8*3%-L8*3%-1) | Q8: =IF(AND(K8<>"",H8>0),(H8-K8)/H8,"") | U8: 100942 | V8: 0667 | W8: SKU idêntico na Olist · CUSTO ZERADO na Olist (conferido hoje) | Y8: ok
A9: Espaço De Bicho | B9: Antipulgas Invicto Cães 11,4 Kg A 57kg 1 Comprimido | C9: Sem variação | D9: 010 | E9: 21169839582 | F9: 0 | G9: NORMAL | H9: 17.9 | I9: 17.9 | J9: NÃO | L9: =IF(K9<>"",K9,I9) | M9: 1 | N9: 6.52 | O9: =ROUND(M9*N9,2) | P9: =IF($O9="","",L9-O9-(L9*IF(L9<=79.99,20%,14%)+IF(L9<=79.99,4,IF(L9<=99.99,16,IF(L9<=199.99,20,IF(L9<=499.99,26,28)))))-L9*1.3%-L9*6%-(L9-O9)*9.25%-L9*3%-L9*3%-1) | Q9: =IF(AND(K9<>"",H9>0),(H9-K9)/H9,"") | U9: 100942 | V9: 213547 | W9: SKU do de-para · custo do KIT 213690 (1× 213547) | X9: 2 | Y9: ok
A10: Espaço De Bicho | B10: Antitóxico Duprat Oral 20ML Cães Gatos | C10: Sem variação | D10: ANTITOXICO-DUPRAT-ORAL-20 ML | E10: 22199050344 | F10: 0 | G10: NORMAL | H10: 59.9 | I10: 18.83 | J10: SIM | K10: 18.83 | L10: =IF(K10<>"",K10,I10) | P10: =IF($O10="","",L10-O10-(L10*IF(L10<=79.99,20%,14%)+IF(L10<=79.99,4,IF(L10<=99.99,16,IF(L10<=199.99,20,IF(L10<=499.99,26,28)))))-L10*1.3%-L10*6%-(L10-O10)*9.25%-L10*3%-L10*3%-1) | Q10: =IF(AND(K10<>"",H10>0),(H10-K10)/H10,"") | R10: 909477973245952 | S10: 46144.383 | T10: 46295.438 | U10: 100942 | V10: ANTITOXICO-DUPRAT-ORAL-20 ML | W10: SKU idêntico na Olist · CUSTO ZERADO na Olist (conferido hoje) | Y10: ok
A11: Espaço De Bicho | B11: Tapete Higienico Good Pad 50 Unidades Envio Imediato | C11: Sem variação | D11: 0771 | E11: 17981944804 | F11: 0 | G11: NORMAL | H11: 99.9 | I11: 44.9 | J11: SIM | K11: 44.9 | L11: =IF(K11<>"",K11,I11) | M11: 1 | N11: 33.46 | O11: =ROUND(M11*N11,2) | P11: =IF($O11="","",L11-O11-(L11*IF(L11<=79.99,20%,14%)+IF(L11<=79.99,4,IF(L11<=99.99,16,IF(L11<=199.99,20,IF(L11<=499.99,26,28)))))-L11*1.3%-L11*6%-(L11-O11)*9.25%-L11*3%-L11*3%-1) | Q11: =IF(AND(K11<>"",H11>0),(H11-K11)/H11,"") | R11: 909477973245952 | S11: 46144.383 | T11: 46295.438 | U11: 100926 | V11: 212961 | W11: venda casada (1160 pedidos) · custo do KIT 213830 (1× 212961) | X11: 1160 | Y11: ok
A12: Espaço De Bicho | B12: Bebedouro Beija Flor Luxo com chapéu e poleiro - Jelplast Sortido | C12: Sem variação | D12: 64 | E12: 18499198968 | F12: 0 | G12: NORMAL | H12: 29.9 | I12: 13.9 | J12: SIM | K12: 13.9 | L12: =IF(K12<>"",K12,I12) | P12: =IF($O12="","",L12-O12-(L12*IF(L12<=79.99,20%,14%)+IF(L12<=79.99,4,IF(L12<=99.99,16,IF(L12<=199.99,20,IF(L12<=499.99,26,28)))))-L12*1.3%-L12*6%-(L12-O12)*9.25%-L12*3%-L12*3%-1) | Q12: =IF(AND(K12<>"",H12>0),(H12-K12)/H12,"") | R12: 909477973245952 | S12: 46144.383 | T12: 46295.438 | U12: 100916 | V12: 64 | W12: SKU idêntico na Olist · CUSTO ZERADO na Olist (conferido hoje) | Y12: ok
A13: Espaço De Bicho | B13: Bolinha Com Guizo Brinquedo Para Gato Colorido | C13: Sem variação | D13: BOLA-GUIZO-CAT | E13: 22993543152 | F13: 0 | G13: NORMAL | H13: 19.9 | I13: 9.9 | J13: SIM | K13: 9.9 | L13: =IF(K13<>"",K13,I13) | M13: 1 | N13: 0.2 | O13: =ROUND(M13*N13,2) | P13: =IF($O13="","",L13-O13-(L13*IF(L13<=79.99,20%,14%)+IF(L13<=79.99,4,IF(L13<=99.99,16,IF(L13<=199.99,20,IF(L13<=499.99,26,28)))))-L13*1.3%-L13*6%-(L13-O13)*9.25%-L13*3%-L13*3%-1) | Q13: =IF(AND(K13<>"",H13>0),(H13-K13)/H13,"") | R13: 909477973245952 | S13: 46144.383 | T13: 46295.438 | U13: 101926 | V13: 212992 | W13: venda casada (25 pedidos) | X13: 25 | Y13: ok
A14: Espaço De Bicho | B14: Brinquedo Interativo P/ Gatos Varinha Arranhador Pena Ratinho | C14: PENA | D14: BRINQUEDO-PENA | E14: 19197811676 | F14: 229409372832 | G14: NORMAL | H14: 59.9 | I14: 19.89 | J14: SIM | K14: 19.89 | L14: =IF(K14<>"",K14,I14) | M14: 1 | N14: 12.2 | O14: =ROUND(M14*N14,2) | P14: =IF($O14="","",L14-O14-(L14*IF(L14<=79.99,20%,14%)+IF(L14<=79.99,4,IF(L14<=99.99,16,IF(L14<=199.99,20,IF(L14<=499.99,26,28)))))-L14*1.3%-L14*6%-(L14-O14)*9.25%-L14*3%-L14*3%-1) | Q14: =IF(AND(K14<>"",H14>0),(H14-K14)/H14,"") | R14: 909477973245952 | S14: 46144.383 | T14: 46295.438 | U14: 101678 | V14: 213556 | W14: venda casada (3 pedidos) | X14: 3 | Y14: ok
A15: Espaço De Bicho | B15: Brinquedo Interativo P/ Gatos Varinha Arranhador Pena Ratinho | C15: RATO | D15: BRINQUEDO-RATO | E15: 19197811676 | F15: 229409372831 | G15: NORMAL | H15: 59.9 | I15: 19.89 | J15: SIM | K15: 19.89 | L15: =IF(K15<>"",K15,I15) | M15: 1 | N15: 12.2 | O15: =ROUND(M15*N15,2) | P15: =IF($O15="","",L15-O15-(L15*IF(L15<=79.99,20%,14%)+IF(L15<=79.99,4,IF(L15<=99.99,16,IF(L15<=199.99,20,IF(L15<=499.99,26,28)))))-L15*1.3%-L15*6%-(L15-O15)*9.25%-L15*3%-L15*3%-1) | Q15: =IF(AND(K15<>"",H15>0),(H15-K15)/H15,"") | R15: 909477973245952 | S15: 46144.383 | T15: 46295.438 | U15: 101678 | V15: 213555 | W15: venda casada (7 pedidos) | X15: 7 | Y15: ok
A16: Espaço De Bicho | B16: Brinquedo Interativo Simulador de Pássaro- Varinha para provocar e estimular gato | C16: Sem variação | D16: BRINQUEDO-VARA-CAT | E16: 20699202925 | F16: 0 | G16: NORMAL | H16: 29.9 | I16: 25.9 | J16: SIM | K16: 25.9 | L16: =IF(K16<>"",K16,I16) | P16: =IF($O16="","",L16-O16-(L16*IF(L16<=79.99,20%,14%)+IF(L16<=79.99,4,IF(L16<=99.99,16,IF(L16<=199.99,20,IF(L16<=499.99,26,28)))))-L16*1.3%-L16*6%-(L16-O16)*9.25%-L16*3%-L16*3%-1) | Q16: =IF(AND(K16<>"",H16>0),(H16-K16)/H16,"") | R16: 909477973245952 | S16: 46144.383 | T16: 46295.438 | U16: 101925 | W16: ambíguo: 213575 (50%) vs BRINQUEDO-VARA-CAT | X16: 2
A17: Espaço De Bicho | B17: Brinquedo Mordedor Osso Bamboo Sabor Bacon Limpeza Dentes Tartaro Truqys | C17: Osso Pequeno | D17: 0332 | E17: 22196102653 | F17: 159766308983 | G17: NORMAL | H17: 44.9 | I17: 19.9 | J17: SIM | K17: 19.9 | L17: =IF(K17<>"",K17,I17) | M17: 1 | N17: 9.93 | O17: =ROUND(M17*N17,2) | P17: =IF($O17="","",L17-O17-(L17*IF(L17<=79.99,20%,14%)+IF(L17<=79.99,4,IF(L17<=99.99,16,IF(L17<=199.99,20,IF(L17<=499.99,26,28)))))-L17*1.3%-L17*6%-(L17-O17)*9.25%-L17*3%-L17*3%-1) | Q17: =IF(AND(K17<>"",H17>0),(H17-K17)/H17,"") | R17: 909477973245952 | S17: 46144.383 | T17: 46295.438 | U17: 101926 | V17: 215138 | W17: venda casada (1 pedido) | X17: 1 | Y17: ⚠ evidência fraca (1 pedido)
A18: Espaço De Bicho | B18: Brinquedo Varinha Gato Penas Pássaro Com Ventosa Fixa No Chão | C18: PRETO | D18: BRINQUEDO-VARA-CAT-PRETO | E18: 19997807516 | F18: 169399702997 | G18: NORMAL | H18: 39.9 | I18: 24.89 | J18: SIM | K18: 24.89 | L18: =IF(K18<>"",K18,I18) | M18: 1 | N18: 4.33 | O18: =ROUND(M18*N18,2) | P18: =IF($O18="","",L18-O18-(L18*IF(L18<=79.99,20%,14%)+IF(L18<=79.99,4,IF(L18<=99.99,16,IF(L18<=199.99,20,IF(L18<=499.99,26,28)))))-L18*1.3%-L18*6%-(L18-O18)*9.25%-L18*3%-L18*3%-1) | Q18: =IF(AND(K18<>"",H18>0),(H18-K18)/H18,"") | R18: 909477973245952 | S18: 46144.383 | T18: 46295.438 | U18: 101925 | V18: 213527 | W18: venda casada (13 pedidos) | X18: 13 | Y18: ok
A19: Espaço De Bicho | B19: Brinquedo Varinha Gato Penas Pássaro Com Ventosa Fixa No Chão | C19: ROSA | D19: BRINQUEDO-VARA-CAT-ROSA | E19: 19997807516 | F19: 169399702996 | G19: NORMAL | H19: 39.9 | I19: 19.9 | J19: SIM | K19: 19.9 | L19: =IF(K19<>"",K19,I19) | M19: 1 | N19: 4.33 | O19: =ROUND(M19*N19,2) | P19: =IF($O19="","",L19-O19-(L19*IF(L19<=79.99,20%,14%)+IF(L19<=79.99,4,IF(L19<=99.99,16,IF(L19<=199.99,20,IF(L19<=499.99,26,28)))))-L19*1.3%-L19*6%-(L19-O19)*9.25%-L19*3%-L19*3%-1) | Q19: =IF(AND(K19<>"",H19>0),(H19-K19)/H19,"") | R19: 909477973245952 | S19: 46144.383 | T19: 46295.438 | U19: 101925 | V19: 213528 | W19: venda casada (57 pedidos) | X19: 57 | Y19: ok
A20: Espaço De Bicho | B20: Cata caca passeio dos pet | C20: Sem variação | D20: 290 | E20: 21499666045 | F20: 0 | G20: NORMAL | H20: 29.9 | I20: 29.9 | J20: NÃO | L20: =IF(K20<>"",K20,I20) | P20: =IF($O20="","",L20-O20-(L20*IF(L20<=79.99,20%,14%)+IF(L20<=79.99,4,IF(L20<=99.99,16,IF(L20<=199.99,20,IF(L20<=499.99,26,28)))))-L20*1.3%-L20*6%-(L20-O20)*9.25%-L20*3%-L20*3%-1) | Q20: =IF(AND(K20<>"",H20>0),(H20-K20)/H20,"") | U20: 100927 | V20: 290 | W20: SKU idêntico na Olist · CUSTO ZERADO na Olist (conferido hoje) | Y20: ok
A21: Espaço De Bicho | B21: Duotrill 150mg 10 Comprimidos Para Cães E Gatos - Duprat | C21: Sem variação | D21: DUOTRILL-150MG-10COMP | E21: 23099049174 | F21: 0 | G21: NORMAL | H21: 99.9 | I21: 56.9 | J21: SIM | K21: 56.9 | L21: =IF(K21<>"",K21,I21) | P21: =IF($O21="","",L21-O21-(L21*IF(L21<=79.99,20%,14%)+IF(L21<=79.99,4,IF(L21<=99.99,16,IF(L21<=199.99,20,IF(L21<=499.99,26,28)))))-L21*1.3%-L21*6%-(L21-O21)*9.25%-L21*3%-L21*3%-1) | Q21: =IF(AND(K21<>"",H21>0),(H21-K21)/H21,"") | R21: 909477973245952 | S21: 46144.383 | T21: 46295.438 | U21: 100944 | V21: DUOTRILL-150MG-10COMP | W21: SKU idêntico na Olist · CUSTO ZERADO na Olist (conferido hoje) | Y21: ok
A22: Espaço De Bicho | B22: Duotrill 50 MG Duprat Blister C/ 10 Comprimidos Cães e Gatos | C22: Sem variação | D22: DUOTRILL-50MG-10-COMP | E22: 22899048121 | F22: 0 | G22: NORMAL | H22: 59.9 | I22: 17.99 | J22: SIM | K22: 17.99 | L22: =IF(K22<>"",K22,I22) | M22: 1 | N22: 8 | O22: =ROUND(M22*N22,2) | P22: =IF($O22="","",L22-O22-(L22*IF(L22<=79.99,20%,14%)+IF(L22<=79.99,4,IF(L22<=99.99,16,IF(L22<=199.99,20,IF(L22<=499.99,26,28)))))-L22*1.3%-L22*6%-(L22-O22)*9.25%-L22*3%-L22*3%-1) | Q22: =IF(AND(K22<>"",H22>0),(H22-K22)/H22,"") | R22: 909477973245952 | S22: 46144.383 | T22: 46295.438 | U22: 100942 | V22: 213398 | W22: venda casada (7 pedidos) | X22: 7 | Y22: ok
A23: Espaço De Bicho | B23: Duprantel Vermífugo Cães e Gatos- 4 Comprimidos - Duprat | C23: Sem variação | D23: DUPRANTEL-660MG-4COMPS | E23: 22999049495 | F23: 0 | G23: NORMAL | H23: 59.9 | I23: 14.9 | J23: SIM | K23: 14.9 | L23: =IF(K23<>"",K23,I23) | M23: 1 | N23: 17.46 | O23: =ROUND(M23*N23,2) | P23: =IF($O23="","",L23-O23-(L23*IF(L23<=79.99,20%,14%)+IF(L23<=79.99,4,IF(L23<=99.99,16,IF(L23<=199.99,20,IF(L23<=499.99,26,28)))))-L23*1.3%-L23*6%-(L23-O23)*9.25%-L23*3%-L23*3%-1) | Q23: =IF(AND(K23<>"",H23>0),(H23-K23)/H23,"") | R23: 909477973245952 | S23: 46144.383 | T23: 46295.438 | U23: 100942 | V23: 212433 | W23: venda casada (3 pedidos) | X23: 3 | Y23: ok
A24: Espaço De Bicho | B24: Duprazol Soluçao Oral 30 ML Anti-Helmíntico Cães e Gatos | C24: Sem variação | D24: DUPRAZOL-ORAL-30 ML | E24: 20599908178 | F24: 0 | G24: NORMAL | H24: 59.9 | I24: 17.9 | J24: SIM | K24: 17.9 | L24: =IF(K24<>"",K24,I24) | M24: 1 | N24: 9.4 | O24: =ROUND(M24*N24,2) | P24: =IF($O24="","",L24-O24-(L24*IF(L24<=79.99,20%,14%)+IF(L24<=79.99,4,IF(L24<=99.99,16,IF(L24<=199.99,20,IF(L24<=499.99,26,28)))))-L24*1.3%-L24*6%-(L24-O24)*9.25%-L24*3%-L24*3%-1) | Q24: =IF(AND(K24<>"",H24>0),(H24-K24)/H24,"") | R24: 909477973245952 | S24: 46144.383 | T24: 46295.438 | U24: 100942 | V24: 213480 | W24: venda casada (2 pedidos) | X24: 2 | Y24: ok
A25: Espaço De Bicho | B25: Gaiola Hamster Tubo 3 Andares Espaco De Bicho Completa com Rodinha | C25: AZUL | D25: GAIOLA-HAMSTER-PEQ-AZ | E25: 22098124819 | F25: 239414033397 | G25: NORMAL | H25: 199.9 | I25: 128.99 | J25: SIM | K25: 128.99 | L25: =IF(K25<>"",K25,I25) | M25: 1 | N25: 71.14 | O25: =ROUND(M25*N25,2) | P25: =IF($O25="","",L25-O25-(L25*IF(L25<=79.99,20%,14%)+IF(L25<=79.99,4,IF(L25<=99.99,16,IF(L25<=199.99,20,IF(L25<=499.99,26,28)))))-L25*1.3%-L25*6%-(L25-O25)*9.25%-L25*3%-L25*3%-1) | Q25: =IF(AND(K25<>"",H25>0),(H25-K25)/H25,"") | R25: 909477973245952 | S25: 46144.383 | T25: 46295.438 | U25: 101684 | V25: 213625 | W25: venda casada (1 pedido) | X25: 1 | Y25: ⚠ evidência fraca (1 pedido)
A26: Espaço De Bicho | B26: Gaiola Hamster Tubo 3 Andares Espaco De Bicho Completa com Rodinha | C26: ROXO | D26: GAIOLA-HAMSTER-PEQ-RX | E26: 22098124819 | F26: 239414033395 | G26: NORMAL | H26: 199.9 | I26: 149.89 | J26: SIM | K26: 149.89 | L26: =IF(K26<>"",K26,I26) | M26: 1 | N26: 71.14 | O26: =ROUND(M26*N26,2) | P26: =IF($O26="","",L26-O26-(L26*IF(L26<=79.99,20%,14%)+IF(L26<=79.99,4,IF(L26<=99.99,16,IF(L26<=199.99,20,IF(L26<=499.99,26,28)))))-L26*1.3%-L26*6%-(L26-O26)*9.25%-L26*3%-L26*3%-1) | Q26: =IF(AND(K26<>"",H26>0),(H26-K26)/H26,"") | R26: 909477973245952 | S26: 46144.383 | T26: 46295.438 | U26: 101684 | V26: 213625 | W26: herdado do anúncio | Y26: ok
A27: Espaço De Bicho | B27: Gaiola Hamster Tubo 3 Andares Espaco De Bicho Completa com Rodinha | C27: VERMELHO | D27: GAIOLA-HAMSTER-PEQ-VM | E27: 22098124819 | F27: 239414033396 | G27: NORMAL | H27: 199.9 | I27: 149.9 | J27: SIM | K27: 149.9 | L27: =IF(K27<>"",K27,I27) | M27: 1 | N27: 71.14 | O27: =ROUND(M27*N27,2) | P27: =IF($O27="","",L27-O27-(L27*IF(L27<=79.99,20%,14%)+IF(L27<=79.99,4,IF(L27<=99.99,16,IF(L27<=199.99,20,IF(L27<=499.99,26,28)))))-L27*1.3%-L27*6%-(L27-O27)*9.25%-L27*3%-L27*3%-1) | Q27: =IF(AND(K27<>"",H27>0),(H27-K27)/H27,"") | R27: 909477973245952 | S27: 46144.383 | T27: 46295.438 | U27: 101684 | V27: 213625 | W27: herdado do anúncio | Y27: ok
A28: Espaço De Bicho | B28: Glicosol Pet 50ml - Lavizoo Suplemento Cães E Gatos | C28: Sem variação | D28: GLICOSOL-50ML | E28: 21199252289 | F28: 0 | G28: NORMAL | H28: 59.9 | I28: 24.9 | J28: SIM | K28: 24.9 | L28: =IF(K28<>"",K28,I28) | P28: =IF($O28="","",L28-O28-(L28*IF(L28<=79.99,20%,14%)+IF(L28<=79.99,4,IF(L28<=99.99,16,IF(L28<=199.99,20,IF(L28<=499.99,26,28)))))-L28*1.3%-L28*6%-(L28-O28)*9.25%-L28*3%-L28*3%-1) | Q28: =IF(AND(K28<>"",H28>0),(H28-K28)/H28,"") | R28: 909477973245952 | S28: 46144.383 | T28: 46295.438 | U28: 100944 | V28: GLICOSOL-50ML | W28: SKU idêntico na Olist · CUSTO ZERADO na Olist (conferido hoje) | Y28: ok
A29: Espaço De Bicho | B29: Granulado De Madeira Higiênico para Gatos Absorve 5x Mais | C29: 10kg | D29: GRANULADO-GATO-10KG | E29: 23297634808 | F29: 179398139975 | G29: NORMAL | H29: 68.9 | I29: 42.9 | J29: SIM | K29: 42.9 | L29: =IF(K29<>"",K29,I29) | M29: 1 | N29: 14.54 | O29: =ROUND(M29*N29,2) | P29: =IF($O29="","",L29-O29-(L29*IF(L29<=79.99,20%,14%)+IF(L29<=79.99,4,IF(L29<=99.99,16,IF(L29<=199.99,20,IF(L29<=499.99,26,28)))))-L29*1.3%-L29*6%-(L29-O29)*9.25%-L29*3%-L29*3%-1) | Q29: =IF(AND(K29<>"",H29>0),(H29-K29)/H29,"") | R29: 909477973245952 | S29: 46144.383 | T29: 46295.438 | U29: 100923 | V29: 213515 | W29: venda casada (51 pedidos) | X29: 51 | Y29: ok
A30: Espaço De Bicho | B30: Granulado De Madeira Higiênico para Gatos Absorve 5x Mais | C30: 20kg | D30: GRANULADO-GATO-20KG | E30: 23297634808 | F30: 169709589663 | G30: NORMAL | H30: 99.9 | I30: 79.89 | J30: SIM | K30: 79.89 | L30: =IF(K30<>"",K30,I30) | M30: 1 | N30: 27.45 | O30: =ROUND(M30*N30,2) | P30: =IF($O30="","",L30-O30-(L30*IF(L30<=79.99,20%,14%)+IF(L30<=79.99,4,IF(L30<=99.99,16,IF(L30<=199.99,20,IF(L30<=499.99,26,28)))))-L30*1.3%-L30*6%-(L30-O30)*9.25%-L30*3%-L30*3%-1) | Q30: =IF(AND(K30<>"",H30>0),(H30-K30)/H30,"") | R30: 909477973245952 | S30: 46144.383 | T30: 46295.438 | U30: 100923 | V30: 213516 | W30: venda casada (36 pedidos) | X30: 36 | Y30: ok
A31: Espaço De Bicho | B31: Granulado De Madeira Higiênico para Gatos Absorve 5x Mais | C31: 2kg | D31: GRANULADO-GATO-2KG | E31: 23297634808 | F31: 179398139973 | G31: NORMAL | H31: 20.9 | I31: 14.9 | J31: NÃO | L31: =IF(K31<>"",K31,I31) | M31: 1 | N31: 2.35 | O31: =ROUND(M31*N31,2) | P31: =IF($O31="","",L31-O31-(L31*IF(L31<=79.99,20%,14%)+IF(L31<=79.99,4,IF(L31<=99.99,16,IF(L31<=199.99,20,IF(L31<=499.99,26,28)))))-L31*1.3%-L31*6%-(L31-O31)*9.25%-L31*3%-L31*3%-1) | Q31: =IF(AND(K31<>"",H31>0),(H31-K31)/H31,"") | U31: 100923 | V31: 213513 | W31: venda casada (9 pedidos) | X31: 9 | Y31: ok
A32: Espaço De Bicho | B32: Granulado De Madeira Higiênico para Gatos Absorve 5x Mais | C32: 4kg | D32: GRANULADO-GATO-4KG | E32: 23297634808 | F32: 179398139974 | G32: NORMAL | H32: 29.9 | I32: 29.59 | J32: SIM | K32: 29.59 | L32: =IF(K32<>"",K32,I32) | M32: 1 | N32: 2.35 | O32: =ROUND(M32*N32,2) | P32: =IF($O32="","",L32-O32-(L32*IF(L32<=79.99,20%,14%)+IF(L32<=79.99,4,IF(L32<=99.99,16,IF(L32<=199.99,20,IF(L32<=499.99,26,28)))))-L32*1.3%-L32*6%-(L32-O32)*9.25%-L32*3%-L32*3%-1) | Q32: =IF(AND(K32<>"",H32>0),(H32-K32)/H32,"") | R32: 909477973245952 | S32: 46144.383 | T32: 46295.438 | U32: 100923 | V32: 213514 | W32: venda casada (17 pedidos) | X32: 17 | Y32: ok
A33: Espaço De Bicho | B33: Invicto 11,4 Mg 6 Comprimidos (antipulgas Até 11,4kg) | C33: Sem variação | D33: 0023 | E33: 22914482891 | F33: 0 | G33: NORMAL | H33: 62.9 | I33: 59.9 | J33: SIM | K33: 59.9 | L33: =IF(K33<>"",K33,I33) | P33: =IF($O33="","",L33-O33-(L33*IF(L33<=79.99,20%,14%)+IF(L33<=79.99,4,IF(L33<=99.99,16,IF(L33<=199.99,20,IF(L33<=499.99,26,28)))))-L33*1.3%-L33*6%-(L33-O33)*9.25%-L33*3%-L33*3%-1) | Q33: =IF(AND(K33<>"",H33>0),(H33-K33)/H33,"") | R33: 909477973245952 | S33: 46144.383 | T33: 46295.438 | U33: 100942 | V33: 0023 | W33: SKU idêntico na Olist · CUSTO ZERADO na Olist (conferido hoje) | Y33: ok
A34: Espaço De Bicho | B34: Invicto 11,4 Mg Cão/gato Antipulga 20 Blister 1 Cp | C34: Sem variação | D34: 0644 | E34: 22914542066 | F34: 0 | G34: NORMAL | H34: 252.9 | I34: 252.9 | J34: NÃO | L34: =IF(K34<>"",K34,I34) | P34: =IF($O34="","",L34-O34-(L34*IF(L34<=79.99,20%,14%)+IF(L34<=79.99,4,IF(L34<=99.99,16,IF(L34<=199.99,20,IF(L34<=499.99,26,28)))))-L34*1.3%-L34*6%-(L34-O34)*9.25%-L34*3%-L34*3%-1) | Q34: =IF(AND(K34<>"",H34>0),(H34-K34)/H34,"") | U34: 100942 | V34: 0644 | W34: SKU idêntico na Olist · CUSTO ZERADO na Olist (conferido hoje) | Y34: ok
A35: Espaço De Bicho | B35: Invicto 57mg Antipulgas P/cães E Gatos De 11,4kg A 57kg - 1 Comprimido | C35: Sem variação | E35: 21997503469 | F35: 0 | G35: NORMAL | H35: 29.9 | I35: 16.9 | J35: SIM | K35: 16.9 | L35: =IF(K35<>"",K35,I35) | P35: =IF($O35="","",L35-O35-(L35*IF(L35<=79.99,20%,14%)+IF(L35<=79.99,4,IF(L35<=99.99,16,IF(L35<=199.99,20,IF(L35<=499.99,26,28)))))-L35*1.3%-L35*6%-(L35-O35)*9.25%-L35*3%-L35*3%-1) | Q35: =IF(AND(K35<>"",H35>0),(H35-K35)/H35,"") | R35: 909477973245952 | S35: 46144.383 | T35: 46295.438 | U35: 100942 | W35: sem correspondência
A36: Jacartta | B36: Tapete Higienico Good Pad 50 Unidades Envio Imediato | C36: Sem variação | D36: 0771 | E36: 17463955532 | F36: 0 | G36: NORMAL | H36: 64.9 | I36: 59.9 | J36: NÃO | L36: =IF(K36<>"",K36,I36) | M36: 1 | N36: 33.46 | O36: =ROUND(M36*N36,2) | P36: =IF($O36="","",L36-O36-(L36*IF(L36<=79.99,20%,14%)+IF(L36<=79.99,4,IF(L36<=99.99,16,IF(L36<=199.99,20,IF(L36<=499.99,26,28)))))-L36*1.3%-L36*6%-(L36-O36)*9.25%-L36*3%-L36*3%-1) | Q36: =IF(AND(K36<>"",H36>0),(H36-K36)/H36,"") | U36: 100926 | V36: 212961 | W36: venda casada (750 pedidos) · custo do KIT 213830 (1× 212961) | X36: 750 | Y36: ok
A37: Espaço De Bicho | B37: Kit 2 Bebedouro Para Beija Flor Aves Passaro Poleiro 250ml | C37: Kit 2 | D37: KIT-2-BEBEDOURO-BEIJAFLOR | E37: 23697343948 | F37: 219174198287 | G37: NORMAL | H37: 59.9 | I37: 19.9 | J37: SIM | K37: 19.9 | L37: =IF(K37<>"",K37,I37) | M37: 2 | N37: 3.35 | O37: =ROUND(M37*N37,2) | P37: =IF($O37="","",L37-O37-(L37*IF(L37<=79.99,20%,14%)+IF(L37<=79.99,4,IF(L37<=99.99,16,IF(L37<=199.99,20,IF(L37<=499.99,26,28)))))-L37*1.3%-L37*6%-(L37-O37)*9.25%-L37*3%-L37*3%-1) | Q37: =IF(AND(K37<>"",H37>0),(H37-K37)/H37,"") | R37: 909477973245952 | S37: 46144.383 | T37: 46295.438 | U37: 100916 | V37: 212811 | W37: venda casada (374 pedidos) · custo do KIT 213561 (2× 212811) | X37: 374 | Y37: ok
A38: Espaço De Bicho | B38: Kit 4 Areia Higiênica Biodegradável Grãos Finos Milho e Mandioca (100% Natural) - Espaço De Bicho | C38: Grãos Finos | D38: KIT4-AREIA-EDB-4KG-GF | E38: 58254481683 | F38: 229437018332 | G38: NORMAL | H38: 199.9 | I38: 199.9 | J38: NÃO | L38: =IF(K38<>"",K38,I38) | P38: =IF($O38="","",L38-O38-(L38*IF(L38<=79.99,20%,14%)+IF(L38<=79.99,4,IF(L38<=99.99,16,IF(L38<=199.99,20,IF(L38<=499.99,26,28)))))-L38*1.3%-L38*6%-(L38-O38)*9.25%-L38*3%-L38*3%-1) | Q38: =IF(AND(K38<>"",H38>0),(H38-K38)/H38,"") | U38: 100923 | W38: ambíguo: 215511 (77%) vs KIT4-AREIA-EDB-4KG-GF | X38: 13
A39: Jacartta | B39: Senspert - Erliquiose | C39: Sem variação | D39: 043 | E39: 14182727107 | F39: 0 | G39: NORMAL | H39: 145.8 | I39: 71.9 | J39: SIM | K39: 71.9 | L39: =IF(K39<>"",K39,I39) | O39: 51.04 | P39: =IF($O39="","",L39-O39-(L39*IF(L39<=79.99,20%,14%)+IF(L39<=79.99,4,IF(L39<=99.99,16,IF(L39<=199.99,20,IF(L39<=499.99,26,28)))))-L39*1.3%-L39*6%-(L39-O39)*9.25%-L39*3%-L39*3%-1) | Q39: =IF(AND(K39<>"",H39>0),(H39-K39)/H39,"") | R39: 909481504866304 | S39: 46144.387 | T39: 46295.438 | U39: 100942 | W39: custo preexistente (busca por texto) mantido
A40: Espaço De Bicho | B40: Kit Protetor De Colchão Lençol Oliver Home G Descartável Cadeira de Rodas Pós Operatório Impermeável | C40: KIT 3 - 15 UNIDADES | D40: 3PCT-PROTETOR-COLCHÃO | E40: 23593573884 | F40: 229413614023 | G40: NORMAL | H40: 89.9 | I40: 73.9 | J40: SIM | K40: 73.9 | L40: =IF(K40<>"",K40,I40) | M40: 3 | N40: 7.31 | O40: =ROUND(M40*N40,2) | P40: =IF($O40="","",L40-O40-(L40*IF(L40<=79.99,20%,14%)+IF(L40<=79.99,4,IF(L40<=99.99,16,IF(L40<=199.99,20,IF(L40<=499.99,26,28)))))-L40*1.3%-L40*6%-(L40-O40)*9.25%-L40*3%-L40*3%-1) | Q40: =IF(AND(K40<>"",H40>0),(H40-K40)/H40,"") | R40: 909477973245952 | S40: 46144.383 | T40: 46295.438 | U40: 101145 | V40: 213170 | W40: venda casada (1 pedido) · custo do KIT 213681 (3× 213170) | X40: 1 | Y40: ⚠ evidência fraca (1 pedido)
...
